2020-04-01 21:03:38,343 ERROR: Exception on /reset_password_request [POST] [in /Users/harry/microblog/venv/lib/python3.7/site-packages/flask/app.py:1891]
Traceback (most recent call last):
  File "/Users/harry/microblog/venv/lib/python3.7/site-packages/flask/app.py", line 2446, in wsgi_app
    response = self.full_dispatch_request()
  File "/Users/harry/microblog/venv/lib/python3.7/site-packages/flask/app.py", line 1951, in full_dispatch_request
    rv = self.handle_user_exception(e)
  File "/Users/harry/microblog/venv/lib/python3.7/site-packages/flask/app.py", line 1820, in handle_user_exception
    reraise(exc_type, exc_value, tb)
  File "/Users/harry/microblog/venv/lib/python3.7/site-packages/flask/_compat.py", line 39, in reraise
    raise value
  File "/Users/harry/microblog/venv/lib/python3.7/site-packages/flask/app.py", line 1949, in full_dispatch_request
    rv = self.dispatch_request()
  File "/Users/harry/microblog/venv/lib/python3.7/site-packages/flask/app.py", line 1935, in dispatch_request
    return self.view_functions[rule.endpoint](**req.view_args)
  File "/Users/harry/microblog/app/routes.py", line 152, in reset_password_request
    send_password_reset_email(user)
  File "/Users/harry/microblog/app/email.py", line 25, in send_password_reset_email
    user=user, token=token))
  File "/Users/harry/microblog/app/email.py", line 14, in send_email
    mail.send(msg)
  File "/Users/harry/microblog/venv/lib/python3.7/site-packages/flask_mail.py", line 491, in send
    with self.connect() as connection:
  File "/Users/harry/microblog/venv/lib/python3.7/site-packages/flask_mail.py", line 144, in __enter__
    self.host = self.configure_host()
  File "/Users/harry/microblog/venv/lib/python3.7/site-packages/flask_mail.py", line 165, in configure_host
    host.login(self.mail.username, self.mail.password)
  File "//miniconda3/lib/python3.7/smtplib.py", line 730, in login
    raise last_exception
  File "//miniconda3/lib/python3.7/smtplib.py", line 721, in login
    initial_response_ok=initial_response_ok)
  File "//miniconda3/lib/python3.7/smtplib.py", line 642, in auth
    raise SMTPAuthenticationError(code, resp)
smtplib.SMTPAuthenticationError: (535, b'5.7.8 Username and Password not accepted. Learn more at\n5.7.8  https://support.google.com/mail/?p=BadCredentials m1sm2810945qtm.22 - gsmtp')
2020-04-01 21:08:01,138 INFO: Microblog startup [in /Users/harry/microblog/app/__init__.py:49]
2020-04-04 00:53:56,353 INFO: Microblog startup [in /Users/harry/microblog/app/__init__.py:53]
2020-04-04 00:54:32,096 INFO: Microblog startup [in /Users/harry/microblog/app/__init__.py:53]
2020-04-04 00:54:35,347 ERROR: Exception on / [GET] [in /Users/harry/microblog/venv/lib/python3.7/site-packages/flask/app.py:1891]
Traceback (most recent call last):
  File "/Users/harry/microblog/venv/lib/python3.7/site-packages/flask/app.py", line 2446, in wsgi_app
    response = self.full_dispatch_request()
  File "/Users/harry/microblog/venv/lib/python3.7/site-packages/flask/app.py", line 1951, in full_dispatch_request
    rv = self.handle_user_exception(e)
  File "/Users/harry/microblog/venv/lib/python3.7/site-packages/flask/app.py", line 1820, in handle_user_exception
    reraise(exc_type, exc_value, tb)
  File "/Users/harry/microblog/venv/lib/python3.7/site-packages/flask/_compat.py", line 39, in reraise
    raise value
  File "/Users/harry/microblog/venv/lib/python3.7/site-packages/flask/app.py", line 1947, in full_dispatch_request
    rv = self.preprocess_request()
  File "/Users/harry/microblog/venv/lib/python3.7/site-packages/flask/app.py", line 2241, in preprocess_request
    rv = func()
  File "/Users/harry/microblog/app/routes.py", line 17, in before_request
    g.locale = str(get_locale())
NameError: name 'g' is not defined
2020-04-04 00:56:18,107 INFO: Microblog startup [in /Users/harry/microblog/app/__init__.py:53]
2020-04-04 00:58:42,435 INFO: Microblog startup [in /Users/harry/microblog/app/__init__.py:53]
2020-04-04 00:58:44,947 ERROR: Exception on /index [GET] [in /Users/harry/microblog/venv/lib/python3.7/site-packages/flask/app.py:1891]
Traceback (most recent call last):
  File "/Users/harry/microblog/venv/lib/python3.7/site-packages/flask/app.py", line 2446, in wsgi_app
    response = self.full_dispatch_request()
  File "/Users/harry/microblog/venv/lib/python3.7/site-packages/flask/app.py", line 1951, in full_dispatch_request
    rv = self.handle_user_exception(e)
  File "/Users/harry/microblog/venv/lib/python3.7/site-packages/flask/app.py", line 1820, in handle_user_exception
    reraise(exc_type, exc_value, tb)
  File "/Users/harry/microblog/venv/lib/python3.7/site-packages/flask/_compat.py", line 39, in reraise
    raise value
  File "/Users/harry/microblog/venv/lib/python3.7/site-packages/flask/app.py", line 1947, in full_dispatch_request
    rv = self.preprocess_request()
  File "/Users/harry/microblog/venv/lib/python3.7/site-packages/flask/app.py", line 2241, in preprocess_request
    rv = func()
  File "/Users/harry/microblog/app/routes.py", line 17, in before_request
    g.locale = str(get_locale())
  File "/Users/harry/microblog/venv/lib/python3.7/site-packages/flask_babel/__init__.py", line 255, in get_locale
    locale = Locale.parse(rv)
  File "/Users/harry/microblog/venv/lib/python3.7/site-packages/babel/core.py", line 268, in parse
    parts = parse_locale(identifier, sep=sep)
  File "/Users/harry/microblog/venv/lib/python3.7/site-packages/babel/core.py", line 1094, in parse_locale
    raise ValueError('expected only letters, got %r' % lang)
ValueError: expected only letters, got 'en-us'
2020-04-04 00:58:48,493 ERROR: Exception on /index [GET] [in /Users/harry/microblog/venv/lib/python3.7/site-packages/flask/app.py:1891]
Traceback (most recent call last):
  File "/Users/harry/microblog/venv/lib/python3.7/site-packages/flask/app.py", line 2446, in wsgi_app
    response = self.full_dispatch_request()
  File "/Users/harry/microblog/venv/lib/python3.7/site-packages/flask/app.py", line 1951, in full_dispatch_request
    rv = self.handle_user_exception(e)
  File "/Users/harry/microblog/venv/lib/python3.7/site-packages/flask/app.py", line 1820, in handle_user_exception
    reraise(exc_type, exc_value, tb)
  File "/Users/harry/microblog/venv/lib/python3.7/site-packages/flask/_compat.py", line 39, in reraise
    raise value
  File "/Users/harry/microblog/venv/lib/python3.7/site-packages/flask/app.py", line 1947, in full_dispatch_request
    rv = self.preprocess_request()
  File "/Users/harry/microblog/venv/lib/python3.7/site-packages/flask/app.py", line 2241, in preprocess_request
    rv = func()
  File "/Users/harry/microblog/app/routes.py", line 17, in before_request
    g.locale = str(get_locale())
  File "/Users/harry/microblog/venv/lib/python3.7/site-packages/flask_babel/__init__.py", line 255, in get_locale
    locale = Locale.parse(rv)
  File "/Users/harry/microblog/venv/lib/python3.7/site-packages/babel/core.py", line 268, in parse
    parts = parse_locale(identifier, sep=sep)
  File "/Users/harry/microblog/venv/lib/python3.7/site-packages/babel/core.py", line 1094, in parse_locale
    raise ValueError('expected only letters, got %r' % lang)
ValueError: expected only letters, got 'en-us'
2020-04-04 00:58:50,421 ERROR: Exception on / [GET] [in /Users/harry/microblog/venv/lib/python3.7/site-packages/flask/app.py:1891]
Traceback (most recent call last):
  File "/Users/harry/microblog/venv/lib/python3.7/site-packages/flask/app.py", line 2446, in wsgi_app
    response = self.full_dispatch_request()
  File "/Users/harry/microblog/venv/lib/python3.7/site-packages/flask/app.py", line 1951, in full_dispatch_request
    rv = self.handle_user_exception(e)
  File "/Users/harry/microblog/venv/lib/python3.7/site-packages/flask/app.py", line 1820, in handle_user_exception
    reraise(exc_type, exc_value, tb)
  File "/Users/harry/microblog/venv/lib/python3.7/site-packages/flask/_compat.py", line 39, in reraise
    raise value
  File "/Users/harry/microblog/venv/lib/python3.7/site-packages/flask/app.py", line 1947, in full_dispatch_request
    rv = self.preprocess_request()
  File "/Users/harry/microblog/venv/lib/python3.7/site-packages/flask/app.py", line 2241, in preprocess_request
    rv = func()
  File "/Users/harry/microblog/app/routes.py", line 17, in before_request
    g.locale = str(get_locale())
  File "/Users/harry/microblog/venv/lib/python3.7/site-packages/flask_babel/__init__.py", line 255, in get_locale
    locale = Locale.parse(rv)
  File "/Users/harry/microblog/venv/lib/python3.7/site-packages/babel/core.py", line 268, in parse
    parts = parse_locale(identifier, sep=sep)
  File "/Users/harry/microblog/venv/lib/python3.7/site-packages/babel/core.py", line 1094, in parse_locale
    raise ValueError('expected only letters, got %r' % lang)
ValueError: expected only letters, got 'en-us'
2020-04-04 01:00:58,739 INFO: Microblog startup [in /Users/harry/microblog/app/__init__.py:53]
2020-04-04 01:34:59,163 INFO: Microblog startup [in /Users/harry/microblog/app/__init__.py:53]
2020-04-04 01:35:12,845 INFO: Microblog startup [in /Users/harry/microblog/app/__init__.py:53]
2020-04-04 01:35:33,898 INFO: Microblog startup [in /Users/harry/microblog/app/__init__.py:53]
2020-04-04 06:04:57,389 INFO: Microblog startup [in /Users/harry/microblog/app/__init__.py:53]
2020-04-04 06:05:05,088 INFO: Microblog startup [in /Users/harry/microblog/app/__init__.py:53]
2020-04-04 06:42:47,337 INFO: Microblog startup [in /Users/harry/microblog/app/__init__.py:53]
2020-04-04 06:43:00,220 INFO: Microblog startup [in /Users/harry/microblog/app/__init__.py:53]
2020-04-04 06:46:40,757 INFO: Microblog startup [in /Users/harry/microblog/app/__init__.py:53]
2020-04-05 01:13:46,649 INFO: Microblog startup [in /Users/harry/microblog/app/__init__.py:77]
2020-04-05 01:13:56,525 INFO: Microblog startup [in /Users/harry/microblog/app/__init__.py:77]
2020-04-05 01:14:03,575 INFO: Microblog startup [in /Users/harry/microblog/app/__init__.py:77]
