2020-02-23 22:47:13,251 INFO: Microblog startup [in /Users/harry/microblog/app/__init__.py:41]
2020-02-23 22:47:25,094 ERROR: Exception on /edit_profile [POST] [in /Users/harry/microblog/venv/lib/python3.7/site-packages/flask/app.py:1891]
Traceback (most recent call last):
  File "/Users/harry/microblog/venv/lib/python3.7/site-packages/flask/app.py", line 2446, in wsgi_app
    response = self.full_dispatch_request()
  File "/Users/harry/microblog/venv/lib/python3.7/site-packages/flask/app.py", line 1951, in full_dispatch_request
    rv = self.handle_user_exception(e)
  File "/Users/harry/microblog/venv/lib/python3.7/site-packages/flask/app.py", line 1820, in handle_user_exception
    reraise(exc_type, exc_value, tb)
  File "/Users/harry/microblog/venv/lib/python3.7/site-packages/flask/_compat.py", line 39, in reraise
    raise value
  File "/Users/harry/microblog/venv/lib/python3.7/site-packages/flask/app.py", line 1949, in full_dispatch_request
    rv = self.dispatch_request()
  File "/Users/harry/microblog/venv/lib/python3.7/site-packages/flask/app.py", line 1935, in dispatch_request
    return self.view_functions[rule.endpoint](**req.view_args)
  File "/Users/harry/microblog/venv/lib/python3.7/site-packages/flask_login/utils.py", line 272, in decorated_view
    return func(*args, **kwargs)
  File "/Users/harry/microblog/app/routes.py", line 83, in edit_profile
    if form.validate_on_submit():
  File "/Users/harry/microblog/venv/lib/python3.7/site-packages/flask_wtf/form.py", line 100, in validate_on_submit
    return self.is_submitted() and self.validate()
  File "/Users/harry/microblog/venv/lib/python3.7/site-packages/wtforms/form.py", line 310, in validate
    return super(Form, self).validate(extra)
  File "/Users/harry/microblog/venv/lib/python3.7/site-packages/wtforms/form.py", line 152, in validate
    if not field.validate(self, extra):
  File "/Users/harry/microblog/venv/lib/python3.7/site-packages/wtforms/fields/core.py", line 206, in validate
    stop_validation = self._run_validation_chain(form, chain)
  File "/Users/harry/microblog/venv/lib/python3.7/site-packages/wtforms/fields/core.py", line 226, in _run_validation_chain
    validator(form, self)
  File "/Users/harry/microblog/app/forms.py", line 39, in validate_username
    if username.data != elf.original_username:
NameError: name 'elf' is not defined
2020-02-23 22:47:47,247 INFO: Microblog startup [in /Users/harry/microblog/app/__init__.py:41]
2020-03-02 12:48:58,308 INFO: Microblog startup [in /Users/harry/microblog/app/__init__.py:41]
2020-03-02 12:49:10,684 INFO: Microblog startup [in /Users/harry/microblog/app/__init__.py:41]
2020-03-09 22:49:35,394 INFO: Microblog startup [in /Users/harry/microblog/app/__init__.py:41]
2020-03-09 22:50:38,716 INFO: Microblog startup [in /Users/harry/microblog/app/__init__.py:41]
2020-03-09 22:55:57,388 INFO: Microblog startup [in /Users/harry/microblog/app/__init__.py:41]
2020-03-09 22:56:10,360 INFO: Microblog startup [in /Users/harry/microblog/app/__init__.py:41]
2020-03-09 22:56:21,008 INFO: Microblog startup [in /Users/harry/microblog/app/__init__.py:41]
2020-03-09 22:58:18,629 INFO: Microblog startup [in /Users/harry/microblog/app/__init__.py:41]
2020-03-09 22:58:48,366 INFO: Microblog startup [in /Users/harry/microblog/app/__init__.py:41]
2020-03-09 23:01:14,374 INFO: Microblog startup [in /Users/harry/microblog/app/__init__.py:41]
2020-03-15 12:38:15,221 INFO: Microblog startup [in /Users/harry/microblog/app/__init__.py:41]
2020-03-15 12:38:48,967 INFO: Microblog startup [in /Users/harry/microblog/app/__init__.py:41]
2020-03-15 12:38:53,472 INFO: Microblog startup [in /Users/harry/microblog/app/__init__.py:41]
2020-03-15 12:41:21,726 INFO: Microblog startup [in /Users/harry/microblog/app/__init__.py:41]
2020-03-15 12:41:57,104 INFO: Microblog startup [in /Users/harry/microblog/app/__init__.py:41]
2020-03-15 12:43:56,428 INFO: Microblog startup [in /Users/harry/microblog/app/__init__.py:41]
2020-03-19 21:27:46,851 INFO: Microblog startup [in /Users/harry/microblog/app/__init__.py:41]
2020-03-19 21:29:32,976 INFO: Microblog startup [in /Users/harry/microblog/app/__init__.py:41]
2020-03-19 21:35:39,351 INFO: Microblog startup [in /Users/harry/microblog/app/__init__.py:41]
2020-03-19 21:35:46,886 ERROR: Exception on / [GET] [in /Users/harry/microblog/venv/lib/python3.7/site-packages/flask/app.py:1891]
Traceback (most recent call last):
  File "/Users/harry/microblog/venv/lib/python3.7/site-packages/flask/app.py", line 2446, in wsgi_app
    response = self.full_dispatch_request()
  File "/Users/harry/microblog/venv/lib/python3.7/site-packages/flask/app.py", line 1951, in full_dispatch_request
    rv = self.handle_user_exception(e)
  File "/Users/harry/microblog/venv/lib/python3.7/site-packages/flask/app.py", line 1820, in handle_user_exception
    reraise(exc_type, exc_value, tb)
  File "/Users/harry/microblog/venv/lib/python3.7/site-packages/flask/_compat.py", line 39, in reraise
    raise value
  File "/Users/harry/microblog/venv/lib/python3.7/site-packages/flask/app.py", line 1949, in full_dispatch_request
    rv = self.dispatch_request()
  File "/Users/harry/microblog/venv/lib/python3.7/site-packages/flask/app.py", line 1935, in dispatch_request
    return self.view_functions[rule.endpoint](**req.view_args)
  File "/Users/harry/microblog/venv/lib/python3.7/site-packages/flask_login/utils.py", line 272, in decorated_view
    return func(*args, **kwargs)
  File "/Users/harry/microblog/app/routes.py", line 22, in index
    return render_template('index.html', title = 'Home Page', form=form, posts=posts)
  File "/Users/harry/microblog/venv/lib/python3.7/site-packages/flask/templating.py", line 138, in render_template
    ctx.app.jinja_env.get_or_select_template(template_name_or_list),
  File "/Users/harry/microblog/venv/lib/python3.7/site-packages/jinja2/environment.py", line 930, in get_or_select_template
    return self.get_template(template_name_or_list, parent, globals)
  File "/Users/harry/microblog/venv/lib/python3.7/site-packages/jinja2/environment.py", line 883, in get_template
    return self._load_template(name, self.make_globals(globals))
  File "/Users/harry/microblog/venv/lib/python3.7/site-packages/jinja2/environment.py", line 857, in _load_template
    template = self.loader.load(self, name, globals)
  File "/Users/harry/microblog/venv/lib/python3.7/site-packages/jinja2/loaders.py", line 129, in load
    code = environment.compile(source, name, filename)
  File "/Users/harry/microblog/venv/lib/python3.7/site-packages/jinja2/environment.py", line 638, in compile
    self.handle_exception(source=source_hint)
  File "/Users/harry/microblog/venv/lib/python3.7/site-packages/jinja2/environment.py", line 832, in handle_exception
    reraise(*rewrite_traceback_stack(source=source))
  File "/Users/harry/microblog/venv/lib/python3.7/site-packages/jinja2/_compat.py", line 28, in reraise
    raise value.with_traceback(tb)
  File "/Users/harry/microblog/app/templates/index.html", line 19, in template
    {% include '_post.html'}
jinja2.exceptions.TemplateSyntaxError: unexpected '}'
2020-03-19 21:37:53,886 INFO: Microblog startup [in /Users/harry/microblog/app/__init__.py:41]
